2023-09-16 03:38:09,562 INFO    Thread-27 :2522018 [wandb_setup.py:_flush():76] Current SDK version is 0.15.10
2023-09-16 03:38:09,562 INFO    Thread-27 :2522018 [wandb_setup.py:_flush():76] Configure stats pid to 2522018
2023-09-16 03:38:09,562 INFO    Thread-27 :2522018 [wandb_setup.py:_flush():76] Loading settings from /home/userfs/j/jrs596/.config/wandb/settings
2023-09-16 03:38:09,562 INFO    Thread-27 :2522018 [wandb_setup.py:_flush():76] Loading settings from /home/userfs/j/jrs596/scripts/Entangled/wandb/settings
2023-09-16 03:38:09,562 INFO    Thread-27 :2522018 [wandb_setup.py:_flush():76] Loading settings from environment variables: {'entity': 'frankslab', 'project': 'Elodea', 'root_dir': '/home/userfs/j/jrs596/scripts/Entangled', 'run_id': 'g3cue6ls', 'sweep_param_path': '/home/userfs/j/jrs596/scripts/Entangled/wandb/sweep-dvp0ulj3/config-g3cue6ls.yaml', 'sweep_id': 'dvp0ulj3'}
2023-09-16 03:38:09,562 INFO    Thread-27 :2522018 [wandb_setup.py:_flush():76] Applying setup settings: {'_disable_service': False}
2023-09-16 03:38:09,562 INFO    Thread-27 :2522018 [wandb_setup.py:_flush():76] Inferring run settings from compute environment: {'program_relpath': 'Torch_Custom_CNNs2.2.1.py', 'program': '/home/userfs/j/jrs596/scripts/Entangled/Torch_Custom_CNNs2.2.1.py'}
2023-09-16 03:38:09,562 INFO    Thread-27 :2522018 [wandb_init.py:_log_setup():524] Logging user logs to /home/userfs/j/jrs596/scripts/Entangled/wandb/run-20230916_033809-g3cue6ls/logs/debug.log
2023-09-16 03:38:09,562 INFO    Thread-27 :2522018 [wandb_init.py:_log_setup():525] Logging internal logs to /home/userfs/j/jrs596/scripts/Entangled/wandb/run-20230916_033809-g3cue6ls/logs/debug-internal.log
2023-09-16 03:38:09,562 INFO    Thread-27 :2522018 [wandb_init.py:init():564] calling init triggers
2023-09-16 03:38:09,563 INFO    Thread-27 :2522018 [wandb_init.py:init():571] wandb.init called with sweep_config: {'input_size': 113}
config: {}
2023-09-16 03:38:09,563 INFO    Thread-27 :2522018 [wandb_init.py:init():614] starting backend
2023-09-16 03:38:09,563 INFO    Thread-27 :2522018 [wandb_init.py:init():618] setting up manager
2023-09-16 03:38:09,570 INFO    Thread-27 :2522018 [backend.py:_multiprocessing_setup():105] multiprocessing start_methods=fork,spawn,forkserver, using: spawn
2023-09-16 03:38:09,570 INFO    Thread-27 :2522018 [wandb_init.py:init():624] backend started and connected
2023-09-16 03:38:09,584 INFO    Thread-27 :2522018 [wandb_run.py:_config_callback():1324] config_cb None None {'input_size': 113}
2023-09-16 03:38:09,586 INFO    Thread-27 :2522018 [wandb_init.py:init():715] updated telemetry
2023-09-16 03:38:09,662 INFO    Thread-27 :2522018 [wandb_init.py:init():748] communicating run to backend with 90.0 second timeout
2023-09-16 03:38:10,055 INFO    Thread-27 :2522018 [wandb_run.py:_on_init():2220] communicating current version
2023-09-16 03:38:10,100 INFO    Thread-27 :2522018 [wandb_run.py:_on_init():2229] got version response 
2023-09-16 03:38:10,100 INFO    Thread-27 :2522018 [wandb_init.py:init():799] starting run threads in backend
2023-09-16 03:38:10,219 INFO    Thread-27 :2522018 [wandb_run.py:_console_start():2199] atexit reg
2023-09-16 03:38:10,219 INFO    Thread-27 :2522018 [wandb_run.py:_redirect():2054] redirect: wrap_raw
2023-09-16 03:38:10,219 INFO    Thread-27 :2522018 [wandb_run.py:_redirect():2119] Wrapping output streams.
2023-09-16 03:38:10,220 INFO    Thread-27 :2522018 [wandb_run.py:_redirect():2144] Redirects installed.
2023-09-16 03:38:10,220 INFO    Thread-27 :2522018 [wandb_init.py:init():840] run started, returning control to user process
2023-09-16 03:46:00,528 INFO    Thread-27 :2522018 [wandb_run.py:_finish():1934] finishing run frankslab/Elodea/g3cue6ls
2023-09-16 03:46:00,528 INFO    Thread-27 :2522018 [wandb_run.py:_atexit_cleanup():2168] got exitcode: 0
2023-09-16 03:46:00,529 INFO    Thread-27 :2522018 [wandb_run.py:_restore():2151] restore
2023-09-16 03:46:00,529 INFO    Thread-27 :2522018 [wandb_run.py:_restore():2157] restore done
2023-09-16 04:51:42,495 INFO    Thread-1  :2522018 [retry.py:__call__():172] Retry attempt failed:
Traceback (most recent call last):
  File "/local/scratch/jrs596/envs/Entangled/lib/python3.8/site-packages/urllib3/connection.py", line 174, in _new_conn
    conn = connection.create_connection(
  File "/local/scratch/jrs596/envs/Entangled/lib/python3.8/site-packages/urllib3/util/connection.py", line 72, in create_connection
    for res in socket.getaddrinfo(host, port, family, socket.SOCK_STREAM):
  File "/local/scratch/jrs596/envs/Entangled/lib/python3.8/socket.py", line 918, in getaddrinfo
    for res in _socket.getaddrinfo(host, port, family, type, proto, flags):
socket.gaierror: [Errno -3] Temporary failure in name resolution

During handling of the above exception, another exception occurred:

Traceback (most recent call last):
  File "/local/scratch/jrs596/envs/Entangled/lib/python3.8/site-packages/urllib3/connectionpool.py", line 703, in urlopen
    httplib_response = self._make_request(
  File "/local/scratch/jrs596/envs/Entangled/lib/python3.8/site-packages/urllib3/connectionpool.py", line 386, in _make_request
    self._validate_conn(conn)
  File "/local/scratch/jrs596/envs/Entangled/lib/python3.8/site-packages/urllib3/connectionpool.py", line 1042, in _validate_conn
    conn.connect()
  File "/local/scratch/jrs596/envs/Entangled/lib/python3.8/site-packages/urllib3/connection.py", line 358, in connect
    self.sock = conn = self._new_conn()
  File "/local/scratch/jrs596/envs/Entangled/lib/python3.8/site-packages/urllib3/connection.py", line 186, in _new_conn
    raise NewConnectionError(
urllib3.exceptions.NewConnectionError: <urllib3.connection.HTTPSConnection object at 0x7fa1c488a700>: Failed to establish a new connection: [Errno -3] Temporary failure in name resolution

During handling of the above exception, another exception occurred:

Traceback (most recent call last):
  File "/local/scratch/jrs596/envs/Entangled/lib/python3.8/site-packages/requests/adapters.py", line 489, in send
    resp = conn.urlopen(
  File "/local/scratch/jrs596/envs/Entangled/lib/python3.8/site-packages/urllib3/connectionpool.py", line 787, in urlopen
    retries = retries.increment(
  File "/local/scratch/jrs596/envs/Entangled/lib/python3.8/site-packages/urllib3/util/retry.py", line 592, in increment
    raise MaxRetryError(_pool, url, error or ResponseError(cause))
urllib3.exceptions.MaxRetryError: HTTPSConnectionPool(host='api.wandb.ai', port=443): Max retries exceeded with url: /graphql (Caused by NewConnectionError('<urllib3.connection.HTTPSConnection object at 0x7fa1c488a700>: Failed to establish a new connection: [Errno -3] Temporary failure in name resolution'))

During handling of the above exception, another exception occurred:

Traceback (most recent call last):
  File "/local/scratch/jrs596/envs/Entangled/lib/python3.8/site-packages/wandb/sdk/lib/retry.py", line 131, in __call__
    result = self._call_fn(*args, **kwargs)
  File "/local/scratch/jrs596/envs/Entangled/lib/python3.8/site-packages/wandb/sdk/internal/internal_api.py", line 358, in execute
    return self.client.execute(*args, **kwargs)  # type: ignore
  File "/local/scratch/jrs596/envs/Entangled/lib/python3.8/site-packages/wandb/vendor/gql-0.2.0/wandb_gql/client.py", line 52, in execute
    result = self._get_result(document, *args, **kwargs)
  File "/local/scratch/jrs596/envs/Entangled/lib/python3.8/site-packages/wandb/vendor/gql-0.2.0/wandb_gql/client.py", line 60, in _get_result
    return self.transport.execute(document, *args, **kwargs)
  File "/local/scratch/jrs596/envs/Entangled/lib/python3.8/site-packages/wandb/sdk/lib/gql_request.py", line 55, in execute
    request = self.session.post(self.url, **post_args)
  File "/local/scratch/jrs596/envs/Entangled/lib/python3.8/site-packages/requests/sessions.py", line 635, in post
    return self.request("POST", url, data=data, json=json, **kwargs)
  File "/local/scratch/jrs596/envs/Entangled/lib/python3.8/site-packages/requests/sessions.py", line 587, in request
    resp = self.send(prep, **send_kwargs)
  File "/local/scratch/jrs596/envs/Entangled/lib/python3.8/site-packages/requests/sessions.py", line 701, in send
    r = adapter.send(request, **kwargs)
  File "/local/scratch/jrs596/envs/Entangled/lib/python3.8/site-packages/requests/adapters.py", line 565, in send
    raise ConnectionError(e, request=request)
requests.exceptions.ConnectionError: HTTPSConnectionPool(host='api.wandb.ai', port=443): Max retries exceeded with url: /graphql (Caused by NewConnectionError('<urllib3.connection.HTTPSConnection object at 0x7fa1c488a700>: Failed to establish a new connection: [Errno -3] Temporary failure in name resolution'))
2023-09-16 04:56:08,943 INFO    Thread-27 :2522018 [wandb_run.py:_footer_history_summary_info():3557] rendering history
2023-09-16 04:56:08,956 INFO    Thread-27 :2522018 [wandb_run.py:_footer_history_summary_info():3589] rendering summary
2023-09-16 04:56:08,965 INFO    Thread-27 :2522018 [wandb_run.py:_footer_sync_info():3516] logging synced files
